Workbook

Sheet 12-month forecast summary
A1: 12-month forecast summary
A2: Susanoo — 12-Month Forecast · Susanoo — Base
A4: Variable / dimension | B4: Value | C4: Value > Susanoo — Growth
A5: 12-month revenue | B5: =SUM(IF(IF(IF(AND('Model inputs'!Q21<=DATE(2026,11,1),DATE(2026,11,1)<=EDATE('Model inputs'!Q21,'Model inputs'!Q18-1*1))="",FALSE,AND('Model inputs'!Q21<=DATE(2026,11,1),DATE(2026,11,1)<=EDATE('Model inputs'!Q21,'Model inputs'!Q18-1*1))),'Monthly revenue cost and runway'!B5,"")="",0,IF(IF(AND('Model inputs'!Q21<=DATE(2026,11,1),DATE(2026,11,1)<=EDATE('Model inputs'!Q21,'Model inputs'!Q18-1*1))="",FALSE,AND('Model inputs'!Q21<=DATE(2026,11,1),DATE(2026,11,1)<=EDATE('Model inputs'!Q21,'Model inputs'!Q18-1*1))),'Monthly revenue cost and runway'!B5,"")),IF(IF(IF(AND('Model inputs'!Q21<=DATE(2026,12,1),DATE(2026,12,1)<=EDATE('Model inputs'!Q21,'Model inputs'!Q18-1*1))="",FALSE,AND('Model inputs'!Q21<=DATE(2026,12,1),DATE(2026,12,1)<=EDATE('Model inputs'!Q21,'Model inputs'!Q18-1*1))),'Monthly revenue cost and runway'!C5,"")="",0,IF(IF(AND('Model inputs'!Q21<=DATE(2026,12,1),DATE(2026,12,1)<=EDATE('Model inputs'!Q21,'Model inputs'!Q18-1*1))="",FALSE,AND('Model inputs'!Q21<=DATE(2026,12,1),DATE(2026,12,1)<=EDATE('Model inputs'!Q21,'Model inputs'!Q18-1*1))),'Monthly revenue cost and runway'!C5,"")),IF(IF(IF(AND('Model inputs'!Q21<=DATE(2027,1,1),DATE(2027,1,1)<=EDATE('Model inputs'!Q21,'Model inputs'!Q18-1*1))="",FALSE,AND('Model inputs'!Q21<=DATE(2027,1,1),DATE(2027,1,1)<=EDATE('Model inputs'!Q21,'Model inputs'!Q18-1*1))),'Monthly revenue cost and runway'!D5,"")="",0,IF(IF(AND('Model inputs'!Q21<=DATE(2027,1,1),DATE(2027,1,1)<=EDATE('Model inputs'!Q21,'Model inputs'!Q18-1*1))="",FALSE,AND('Model inputs'!Q21<=DATE(2027,1,1),DATE(2027,1,1)<=EDATE('Model inputs'!Q21,'Model inputs'!Q18-1*1))),'Monthly revenue cost and runway'!D5,"")),IF(IF(IF(AND('Model inputs'!Q21<=DATE(2027,2,1),DATE(2027,2,1)<=EDATE('Model inputs'!Q21,'Model inputs'!Q18-1*1))="",FALSE,AND('Model inputs'!Q21<=DATE(2027,2,1),DATE(2027,2,1)<=EDATE('Model inputs'!Q21,'Model inputs'!Q18-1*1))),'Monthly revenue cost and runway'!E5,"")="",0,IF(IF(AND('Model inputs'!Q21<=DATE(2027,2,1),DATE(2027,2,1)<=EDATE('Model inputs'!Q21,'Model inputs'!Q18-1*1))="",FALSE,AND('Model inputs'!Q21<=DATE(2027,2,1),DATE(2027,2,1)<=EDATE('Model inputs'!Q21,'Model inputs'!Q18-1*1))),'Monthly revenue cost and runway'!E5,"")),IF(IF(IF(AND('Model inputs'!Q21<=DATE(2027,3,1),DATE(2027,3,1)<=EDATE('Model inputs'!Q21,'Model inputs'!Q18-1*1))="",FALSE,AND('Model inputs'!Q21<=DATE(2027,3,1),DATE(2027,3,1)<=EDATE('Model inputs'!Q21,'Model inputs'!Q18-1*1))),'Monthly revenue cost and runway'!F5,"")="",0,IF(IF(AND('Model inputs'!Q21<=DATE(2027,3,1),DATE(2027,3,1)<=EDATE('Model inputs'!Q21,'Model inputs'!Q18-1*1))="",FALSE,AND('Model inputs'!Q21<=DATE(2027,3,1),DATE(2027,3,1)<=EDATE('Model inputs'!Q21,'Model inputs'!Q18-1*1))),'Monthly revenue cost and runway'!F5,"")),IF(IF(IF(AND('Model inputs'!Q21<=DATE(2027,4,1),DATE(2027,4,1)<=EDATE('Model inputs'!Q21,'Model inputs'!Q18-1*1))="",FALSE,AND('Model inputs'!Q21<=DATE(2027,4,1),DATE(2027,4,1)<=EDATE('Model inputs'!Q21,'Model inputs'!Q18-1*1))),'Monthly revenue cost and runway'!G5,"")="",0,IF(IF(AND('Model inputs'!Q21<=DATE(2027,4,1),DATE(2027,4,1)<=EDATE('Model inputs'!Q21,'Model inputs'!Q18-1*1))="",FALSE,AND('Model inputs'!Q21<=DATE(2027,4,1),DATE(2027,4,1)<=EDATE('Model inputs'!Q21,'Model inputs'!Q18-1*1))),'Monthly revenue cost and runway'!G5,"")),IF(IF(IF(AND('Model inputs'!Q21<=DATE(2027,5,1),DATE(2027,5,1)<=EDATE('Model inputs'!Q21,'Model inputs'!Q18-1*1))="",FALSE,AND('Model inputs'!Q21<=DATE(2027,5,1),DATE(2027,5,1)<=EDATE('Model inputs'!Q21,'Model inputs'!Q18-1*1))),'Monthly revenue cost and runway'!H5,"")="",0,IF(IF(AND('Model inputs'!Q21<=DATE(2027,5,1),DATE(2027,5,1)<=EDATE('Model inputs'!Q21,'Model inputs'!Q18-1*1))="",FALSE,AND('Model inputs'!Q21<=DATE(2027,5,1),DATE(2027,5,1)<=EDATE('Model inputs'!Q21,'Model inputs'!Q18-1*1))),'Monthly revenue cost and runway'!H5,"")),IF(IF(IF(AND('Model inputs'!Q21<=DATE(2027,6,1),DATE(2027,6,1)<=EDATE('Model inputs'!Q21,'Model inputs'!Q18-1*1))="",FALSE,AND('Model inputs'!Q21<=DATE(2027,6,1),DATE(2027,6,1)<=EDATE('Model inputs'!Q21,'Model inputs'!Q18-1*1))),'Monthly revenue cost and runway'!I5,"")="",0,IF(IF(AND('Model inputs'!Q21<=DATE(2027,6,1),DATE(2027,6,1)<=EDATE('Model inputs'!Q21,'Model inputs'!Q18-1*1))="",FALSE,AND('Model inputs'!Q21<=DATE(2027,6,1),DATE(2027,6,1)<=EDATE('Model inputs'!Q21,'Model inputs'!Q18-1*1))),'Monthly revenue cost and runway'!I5,"")),IF(IF(IF(AND('Model inputs'!Q21<=DATE(2027,7,1),DATE(2027,7,1)<=EDATE('Model inputs'!Q21,'Model inputs'!Q18-1*1))="",FALSE,AND('Model inputs'!Q21<=DATE(2027,7,1),DATE(2027,7,1)<=EDATE('Model inputs'!Q21,'Model inputs'!Q18-1*1))),'Monthly revenue cost and runway'!J5,"")="",0,IF(IF(AND('Model inputs'!Q21<=DATE(2027,7,1),DATE(2027,7,1)<=EDATE('Model inputs'!Q21,'Model inputs'!Q18-1*1))="",FALSE,AND('Model inputs'!Q21<=DATE(2027,7,1),DATE(2027,7,1)<=EDATE('Model inputs'!Q21,'Model inputs'!Q18-1*1))),'Monthly revenue cost and runway'!J5,"")),IF(IF(IF(AND('Model inputs'!Q21<=DATE(2027,8,1),DATE(2027,8,1)<=EDATE('Model inputs'!Q21,'Model inputs'!Q18-1*1))="",FALSE,AND('Model inputs'!Q21<=DATE(2027,8,1),DATE(2027,8,1)<=EDATE('Model inputs'!Q21,'Model inputs'!Q18-1*1))),'Monthly revenue cost and runway'!K5,"")="",0,IF(IF(AND('Model inputs'!Q21<=DATE(2027,8,1),DATE(2027,8,1)<=EDATE('Model inputs'!Q21,'Model inputs'!Q18-1*1))="",FALSE,AND('Model inputs'!Q21<=DATE(2027,8,1),DATE(2027,8,1)<=EDATE('Model inputs'!Q21,'Model inputs'!Q18-1*1))),'Monthly revenue cost and runway'!K5,"")),IF(IF(IF(AND('Model inputs'!Q21<=DATE(2027,9,1),DATE(2027,9,1)<=EDATE('Model inputs'!Q21,'Model inputs'!Q18-1*1))="",FALSE,AND('Model inputs'!Q21<=DATE(2027,9,1),DATE(2027,9,1)<=EDATE('Model inputs'!Q21,'Model inputs'!Q18-1*1))),'Monthly revenue cost and runway'!L5,"")="",0,IF(IF(AND('Model inputs'!Q21<=DATE(2027,9,1),DATE(2027,9,1)<=EDATE('Model inputs'!Q21,'Model inputs'!Q18-1*1))="",FALSE,AND('Model inputs'!Q21<=DATE(2027,9,1),DATE(2027,9,1)<=EDATE('Model inputs'!Q21,'Model inputs'!Q18-1*1))),'Monthly revenue cost and runway'!L5,"")),IF(IF(IF(AND('Model inputs'!Q21<=DATE(2027,10,1),DATE(2027,10,1)<=EDATE('Model inputs'!Q21,'Model inputs'!Q18-1*1))="",FALSE,AND('Model inputs'!Q21<=DATE(2027,10,1),DATE(2027,10,1)<=EDATE('Model inputs'!Q21,'Model inputs'!Q18-1*1))),'Monthly revenue cost and runway'!M5,"")="",0,IF(IF(AND('Model inputs'!Q21<=DATE(2027,10,1),DATE(2027,10,1)<=EDATE('Model inputs'!Q21,'Model inputs'!Q18-1*1))="",FALSE,AND('Model inputs'!Q21<=DATE(2027,10,1),DATE(2027,10,1)<=EDATE('Model inputs'!Q21,'Model inputs'!Q18-1*1))),'Monthly revenue cost and runway'!M5,"")),IF(IF(IF(AND('Model inputs'!Q21<=DATE(2026,9,1),DATE(2026,9,1)<=EDATE('Model inputs'!Q21,'Model inputs'!Q18-1*1))="",FALSE,AND('Model inputs'!Q21<=DATE(2026,9,1),DATE(2026,9,1)<=EDATE('Model inputs'!Q21,'Model inputs'!Q18-1*1))),'Model inputs'!C24,"")="",0,IF(IF(AND('Model inputs'!Q21<=DATE(2026,9,1),DATE(2026,9,1)<=EDATE('Model inputs'!Q21,'Model inputs'!Q18-1*1))="",FALSE,AND('Model inputs'!Q21<=DATE(2026,9,1),DATE(2026,9,1)<=EDATE('Model inputs'!Q21,'Model inputs'!Q18-1*1))),'Model inputs'!C24,"")),IF(IF(IF(AND('Model inputs'!Q21<=DATE(2026,10,1),DATE(2026,10,1)<=EDATE('Model inputs'!Q21,'Model inputs'!Q18-1*1))="",FALSE,AND('Model inputs'!Q21<=DATE(2026,10,1),DATE(2026,10,1)<=EDATE('Model inputs'!Q21,'Model inputs'!Q18-1*1))),'Model inputs'!D24,"")="",0,IF(IF(AND('Model inputs'!Q21<=DATE(2026,10,1),DATE(2026,10,1)<=EDATE('Model inputs'!Q21,'Model inputs'!Q18-1*1))="",FALSE,AND('Model inputs'!Q21<=DATE(2026,10,1),DATE(2026,10,1)<=EDATE('Model inputs'!Q21,'Model inputs'!Q18-1*1))),'Model inputs'!D24,""))) -> 25908 | C5: =SUM(IF(IF(IF(AND('Model inputs'!Q23<=DATE(2026,10,1),DATE(2026,10,1)<=EDATE('Model inputs'!Q23,'Model inputs'!Q20-1*1))="",FALSE,AND('Model inputs'!Q23<=DATE(2026,10,1),DATE(2026,10,1)<=EDATE('Model inputs'!Q23,'Model inputs'!Q20-1*1))),'Model inputs'!D29,"")="",0,IF(IF(AND('Model inputs'!Q23<=DATE(2026,10,1),DATE(2026,10,1)<=EDATE('Model inputs'!Q23,'Model inputs'!Q20-1*1))="",FALSE,AND('Model inputs'!Q23<=DATE(2026,10,1),DATE(2026,10,1)<=EDATE('Model inputs'!Q23,'Model inputs'!Q20-1*1))),'Model inputs'!D29,"")),IF(IF(IF(AND('Model inputs'!Q23<=DATE(2026,11,1),DATE(2026,11,1)<=EDATE('Model inputs'!Q23,'Model inputs'!Q20-1*1))="",FALSE,AND('Model inputs'!Q23<=DATE(2026,11,1),DATE(2026,11,1)<=EDATE('Model inputs'!Q23,'Model inputs'!Q20-1*1))),'Model inputs'!E29,"")="",0,IF(IF(AND('Model inputs'!Q23<=DATE(2026,11,1),DATE(2026,11,1)<=EDATE('Model inputs'!Q23,'Model inputs'!Q20-1*1))="",FALSE,AND('Model inputs'!Q23<=DATE(2026,11,1),DATE(2026,11,1)<=EDATE('Model inputs'!Q23,'Model inputs'!Q20-1*1))),'Model inputs'!E29,"")),IF(IF(IF(AND('Model inputs'!Q23<=DATE(2026,12,1),DATE(2026,12,1)<=EDATE('Model inputs'!Q23,'Model inputs'!Q20-1*1))="",FALSE,AND('Model inputs'!Q23<=DATE(2026,12,1),DATE(2026,12,1)<=EDATE('Model inputs'!Q23,'Model inputs'!Q20-1*1))),'Model inputs'!F29,"")="",0,IF(IF(AND('Model inputs'!Q23<=DATE(2026,12,1),DATE(2026,12,1)<=EDATE('Model inputs'!Q23,'Model inputs'!Q20-1*1))="",FALSE,AND('Model inputs'!Q23<=DATE(2026,12,1),DATE(2026,12,1)<=EDATE('Model inputs'!Q23,'Model inputs'!Q20-1*1))),'Model inputs'!F29,"")),IF(IF(IF(AND('Model inputs'!Q23<=DATE(2027,1,1),DATE(2027,1,1)<=EDATE('Model inputs'!Q23,'Model inputs'!Q20-1*1))="",FALSE,AND('Model inputs'!Q23<=DATE(2027,1,1),DATE(2027,1,1)<=EDATE('Model inputs'!Q23,'Model inputs'!Q20-1*1))),'Model inputs'!G29,"")="",0,IF(IF(AND('Model inputs'!Q23<=DATE(2027,1,1),DATE(2027,1,1)<=EDATE('Model inputs'!Q23,'Model inputs'!Q20-1*1))="",FALSE,AND('Model inputs'!Q23<=DATE(2027,1,1),DATE(2027,1,1)<=EDATE('Model inputs'!Q23,'Model inputs'!Q20-1*1))),'Model inputs'!G29,"")),IF(IF(IF(AND('Model inputs'!Q23<=DATE(2027,2,1),DATE(2027,2,1)<=EDATE('Model inputs'!Q23,'Model inputs'!Q20-1*1))="",FALSE,AND('Model inputs'!Q23<=DATE(2027,2,1),DATE(2027,2,1)<=EDATE('Model inputs'!Q23,'Model inputs'!Q20-1*1))),'Model inputs'!H29,"")="",0,IF(IF(AND('Model inputs'!Q23<=DATE(2027,2,1),DATE(2027,2,1)<=EDATE('Model inputs'!Q23,'Model inputs'!Q20-1*1))="",FALSE,AND('Model inputs'!Q23<=DATE(2027,2,1),DATE(2027,2,1)<=EDATE('Model inputs'!Q23,'Model inputs'!Q20-1*1))),'Model inputs'!H29,"")),IF(IF(IF(AND('Model inputs'!Q23<=DATE(2027,3,1),DATE(2027,3,1)<=EDATE('Model inputs'!Q23,'Model inputs'!Q20-1*1))="",FALSE,AND('Model inputs'!Q23<=DATE(2027,3,1),DATE(2027,3,1)<=EDATE('Model inputs'!Q23,'Model inputs'!Q20-1*1))),'Model inputs'!I29,"")="",0,IF(IF(AND('Model inputs'!Q23<=DATE(2027,3,1),DATE(2027,3,1)<=EDATE('Model inputs'!Q23,'Model inputs'!Q20-1*1))="",FALSE,AND('Model inputs'!Q23<=DATE(2027,3,1),DATE(2027,3,1)<=EDATE('Model inputs'!Q23,'Model inputs'!Q20-1*1))),'Model inputs'!I29,"")),IF(IF(IF(AND('Model inputs'!Q23<=DATE(2027,4,1),DATE(2027,4,1)<=EDATE('Model inputs'!Q23,'Model inputs'!Q20-1*1))="",FALSE,AND('Model inputs'!Q23<=DATE(2027,4,1),DATE(2027,4,1)<=EDATE('Model inputs'!Q23,'Model inputs'!Q20-1*1))),'Model inputs'!J29,"")="",0,IF(IF(AND('Model inputs'!Q23<=DATE(2027,4,1),DATE(2027,4,1)<=EDATE('Model inputs'!Q23,'Model inputs'!Q20-1*1))="",FALSE,AND('Model inputs'!Q23<=DATE(2027,4,1),DATE(2027,4,1)<=EDATE('Model inputs'!Q23,'Model inputs'!Q20-1*1))),'Model inputs'!J29,"")),IF(IF(IF(AND('Model inputs'!Q23<=DATE(2027,5,1),DATE(2027,5,1)<=EDATE('Model inputs'!Q23,'Model inputs'!Q20-1*1))="",FALSE,AND('Model inputs'!Q23<=DATE(2027,5,1),DATE(2027,5,1)<=EDATE('Model inputs'!Q23,'Model inputs'!Q20-1*1))),'Model inputs'!K29,"")="",0,IF(IF(AND('Model inputs'!Q23<=DATE(2027,5,1),DATE(2027,5,1)<=EDATE('Model inputs'!Q23,'Model inputs'!Q20-1*1))="",FALSE,AND('Model inputs'!Q23<=DATE(2027,5,1),DATE(2027,5,1)<=EDATE('Model inputs'!Q23,'Model inputs'!Q20-1*1))),'Model inputs'!K29,"")),IF(IF(IF(AND('Model inputs'!Q23<=DATE(2027,6,1),DATE(2027,6,1)<=EDATE('Model inputs'!Q23,'Model inputs'!Q20-1*1))="",FALSE,AND('Model inputs'!Q23<=DATE(2027,6,1),DATE(2027,6,1)<=EDATE('Model inputs'!Q23,'Model inputs'!Q20-1*1))),'Model inputs'!L29,"")="",0,IF(IF(AND('Model inputs'!Q23<=DATE(2027,6,1),DATE(2027,6,1)<=EDATE('Model inputs'!Q23,'Model inputs'!Q20-1*1))="",FALSE,AND('Model inputs'!Q23<=DATE(2027,6,1),DATE(2027,6,1)<=EDATE('Model inputs'!Q23,'Model inputs'!Q20-1*1))),'Model inputs'!L29,"")),IF(IF(IF(AND('Model inputs'!Q23<=DATE(2027,7,1),DATE(2027,7,1)<=EDATE('Model inputs'!Q23,'Model inputs'!Q20-1*1))="",FALSE,AND('Model inputs'!Q23<=DATE(2027,7,1),DATE(2027,7,1)<=EDATE('Model inputs'!Q23,'Model inputs'!Q20-1*1))),'Model inputs'!M29,"")="",0,IF(IF(AND('Model inputs'!Q23<=DATE(2027,7,1),DATE(2027,7,1)<=EDATE('Model inputs'!Q23,'Model inputs'!Q20-1*1))="",FALSE,AND('Model inputs'!Q23<=DATE(2027,7,1),DATE(2027,7,1)<=EDATE('Model inputs'!Q23,'Model inputs'!Q20-1*1))),'Model inputs'!M29,"")),IF(IF(IF(AND('Model inputs'!Q23<=DATE(2027,8,1),DATE(2027,8,1)<=EDATE('Model inputs'!Q23,'Model inputs'!Q20-1*1))="",FALSE,AND('Model inputs'!Q23<=DATE(2027,8,1),DATE(2027,8,1)<=EDATE('Model inputs'!Q23,'Model inputs'!Q20-1*1))),'Model inputs'!N29,"")="",0,IF(IF(AND('Model inputs'!Q23<=DATE(2027,8,1),DATE(2027,8,1)<=EDATE('Model inputs'!Q23,'Model inputs'!Q20-1*1))="",FALSE,AND('Model inputs'!Q23<=DATE(2027,8,1),DATE(2027,8,1)<=EDATE('Model inputs'!Q23,'Model inputs'!Q20-1*1))),'Model inputs'!N29,"")),IF(IF(IF(AND('Model inputs'!Q23<=DATE(2027,9,1),DATE(2027,9,1)<=EDATE('Model inputs'!Q23,'Model inputs'!Q20-1*1))="",FALSE,AND('Model inputs'!Q23<=DATE(2027,9,1),DATE(2027,9,1)<=EDATE('Model inputs'!Q23,'Model inputs'!Q20-1*1))),'Model inputs'!O29,"")="",0,IF(IF(AND('Model inputs'!Q23<=DATE(2027,9,1),DATE(2027,9,1)<=EDATE('Model inputs'!Q23,'Model inputs'!Q20-1*1))="",FALSE,AND('Model inputs'!Q23<=DATE(2027,9,1),DATE(2027,9,1)<=EDATE('Model inputs'!Q23,'Model inputs'!Q20-1*1))),'Model inputs'!O29,"")),IF(IF(IF(AND('Model inputs'!Q23<=DATE(2027,10,1),DATE(2027,10,1)<=EDATE('Model inputs'!Q23,'Model inputs'!Q20-1*1))="",FALSE,AND('Model inputs'!Q23<=DATE(2027,10,1),DATE(2027,10,1)<=EDATE('Model inputs'!Q23,'Model inputs'!Q20-1*1))),'Model inputs'!P29,"")="",0,IF(IF(AND('Model inputs'!Q23<=DATE(2027,10,1),DATE(2027,10,1)<=EDATE('Model inputs'!Q23,'Model inputs'!Q20-1*1))="",FALSE,AND('Model inputs'!Q23<=DATE(2027,10,1),DATE(2027,10,1)<=EDATE('Model inputs'!Q23,'Model inputs'!Q20-1*1))),'Model inputs'!P29,"")),IF(IF(IF(AND('Model inputs'!Q23<=DATE(2026,9,1),DATE(2026,9,1)<=EDATE('Model inputs'!Q23,'Model inputs'!Q20-1*1))="",FALSE,AND('Model inputs'!Q23<=DATE(2026,9,1),DATE(2026,9,1)<=EDATE('Model inputs'!Q23,'Model inputs'!Q20-1*1))),'Model inputs'!C104,"")="",0,IF(IF(AND('Model inputs'!Q23<=DATE(2026,9,1),DATE(2026,9,1)<=EDATE('Model inputs'!Q23,'Model inputs'!Q20-1*1))="",FALSE,AND('Model inputs'!Q23<=DATE(2026,9,1),DATE(2026,9,1)<=EDATE('Model inputs'!Q23,'Model inputs'!Q20-1*1))),'Model inputs'!C104,""))) -> 97470
A6: 12-month costs | B6: =SUM(IF(IF(IF(AND('Model inputs'!Q21<=DATE(2026,11,1),DATE(2026,11,1)<=EDATE('Model inputs'!Q21,'Model inputs'!Q18-1*1))="",FALSE,AND('Model inputs'!Q21<=DATE(2026,11,1),DATE(2026,11,1)<=EDATE('Model inputs'!Q21,'Model inputs'!Q18-1*1))),'Monthly revenue cost and runway'!B16,"")="",0,IF(IF(AND('Model inputs'!Q21<=DATE(2026,11,1),DATE(2026,11,1)<=EDATE('Model inputs'!Q21,'Model inputs'!Q18-1*1))="",FALSE,AND('Model inputs'!Q21<=DATE(2026,11,1),DATE(2026,11,1)<=EDATE('Model inputs'!Q21,'Model inputs'!Q18-1*1))),'Monthly revenue cost and runway'!B16,"")),IF(IF(IF(AND('Model inputs'!Q21<=DATE(2026,12,1),DATE(2026,12,1)<=EDATE('Model inputs'!Q21,'Model inputs'!Q18-1*1))="",FALSE,AND('Model inputs'!Q21<=DATE(2026,12,1),DATE(2026,12,1)<=EDATE('Model inputs'!Q21,'Model inputs'!Q18-1*1))),'Monthly revenue cost and runway'!C16,"")="",0,IF(IF(AND('Model inputs'!Q21<=DATE(2026,12,1),DATE(2026,12,1)<=EDATE('Model inputs'!Q21,'Model inputs'!Q18-1*1))="",FALSE,AND('Model inputs'!Q21<=DATE(2026,12,1),DATE(2026,12,1)<=EDATE('Model inputs'!Q21,'Model inputs'!Q18-1*1))),'Monthly revenue cost and runway'!C16,"")),IF(IF(IF(AND('Model inputs'!Q21<=DATE(2027,1,1),DATE(2027,1,1)<=EDATE('Model inputs'!Q21,'Model inputs'!Q18-1*1))="",FALSE,AND('Model inputs'!Q21<=DATE(2027,1,1),DATE(2027,1,1)<=EDATE('Model inputs'!Q21,'Model inputs'!Q18-1*1))),'Monthly revenue cost and runway'!D16,"")="",0,IF(IF(AND('Model inputs'!Q21<=DATE(2027,1,1),DATE(2027,1,1)<=EDATE('Model inputs'!Q21,'Model inputs'!Q18-1*1))="",FALSE,AND('Model inputs'!Q21<=DATE(2027,1,1),DATE(2027,1,1)<=EDATE('Model inputs'!Q21,'Model inputs'!Q18-1*1))),'Monthly revenue cost and runway'!D16,"")),IF(IF(IF(AND('Model inputs'!Q21<=DATE(2027,2,1),DATE(2027,2,1)<=EDATE('Model inputs'!Q21,'Model inputs'!Q18-1*1))="",FALSE,AND('Model inputs'!Q21<=DATE(2027,2,1),DATE(2027,2,1)<=EDATE('Model inputs'!Q21,'Model inputs'!Q18-1*1))),'Monthly revenue cost and runway'!E16,"")="",0,IF(IF(AND('Model inputs'!Q21<=DATE(2027,2,1),DATE(2027,2,1)<=EDATE('Model inputs'!Q21,'Model inputs'!Q18-1*1))="",FALSE,AND('Model inputs'!Q21<=DATE(2027,2,1),DATE(2027,2,1)<=EDATE('Model inputs'!Q21,'Model inputs'!Q18-1*1))),'Monthly revenue cost and runway'!E16,"")),IF(IF(IF(AND('Model inputs'!Q21<=DATE(2027,3,1),DATE(2027,3,1)<=EDATE('Model inputs'!Q21,'Model inputs'!Q18-1*1))="",FALSE,AND('Model inputs'!Q21<=DATE(2027,3,1),DATE(2027,3,1)<=EDATE('Model inputs'!Q21,'Model inputs'!Q18-1*1))),'Monthly revenue cost and runway'!F16,"")="",0,IF(IF(AND('Model inputs'!Q21<=DATE(2027,3,1),DATE(2027,3,1)<=EDATE('Model inputs'!Q21,'Model inputs'!Q18-1*1))="",FALSE,AND('Model inputs'!Q21<=DATE(2027,3,1),DATE(2027,3,1)<=EDATE('Model inputs'!Q21,'Model inputs'!Q18-1*1))),'Monthly revenue cost and runway'!F16,"")),IF(IF(IF(AND('Model inputs'!Q21<=DATE(2027,4,1),DATE(2027,4,1)<=EDATE('Model inputs'!Q21,'Model inputs'!Q18-1*1))="",FALSE,AND('Model inputs'!Q21<=DATE(2027,4,1),DATE(2027,4,1)<=EDATE('Model inputs'!Q21,'Model inputs'!Q18-1*1))),'Monthly revenue cost and runway'!G16,"")="",0,IF(IF(AND('Model inputs'!Q21<=DATE(2027,4,1),DATE(2027,4,1)<=EDATE('Model inputs'!Q21,'Model inputs'!Q18-1*1))="",FALSE,AND('Model inputs'!Q21<=DATE(2027,4,1),DATE(2027,4,1)<=EDATE('Model inputs'!Q21,'Model inputs'!Q18-1*1))),'Monthly revenue cost and runway'!G16,"")),IF(IF(IF(AND('Model inputs'!Q21<=DATE(2027,5,1),DATE(2027,5,1)<=EDATE('Model inputs'!Q21,'Model inputs'!Q18-1*1))="",FALSE,AND('Model inputs'!Q21<=DATE(2027,5,1),DATE(2027,5,1)<=EDATE('Model inputs'!Q21,'Model inputs'!Q18-1*1))),'Monthly revenue cost and runway'!H16,"")="",0,IF(IF(AND('Model inputs'!Q21<=DATE(2027,5,1),DATE(2027,5,1)<=EDATE('Model inputs'!Q21,'Model inputs'!Q18-1*1))="",FALSE,AND('Model inputs'!Q21<=DATE(2027,5,1),DATE(2027,5,1)<=EDATE('Model inputs'!Q21,'Model inputs'!Q18-1*1))),'Monthly revenue cost and runway'!H16,"")),IF(IF(IF(AND('Model inputs'!Q21<=DATE(2027,6,1),DATE(2027,6,1)<=EDATE('Model inputs'!Q21,'Model inputs'!Q18-1*1))="",FALSE,AND('Model inputs'!Q21<=DATE(2027,6,1),DATE(2027,6,1)<=EDATE('Model inputs'!Q21,'Model inputs'!Q18-1*1))),'Monthly revenue cost and runway'!I16,"")="",0,IF(IF(AND('Model inputs'!Q21<=DATE(2027,6,1),DATE(2027,6,1)<=EDATE('Model inputs'!Q21,'Model inputs'!Q18-1*1))="",FALSE,AND('Model inputs'!Q21<=DATE(2027,6,1),DATE(2027,6,1)<=EDATE('Model inputs'!Q21,'Model inputs'!Q18-1*1))),'Monthly revenue cost and runway'!I16,"")),IF(IF(IF(AND('Model inputs'!Q21<=DATE(2027,7,1),DATE(2027,7,1)<=EDATE('Model inputs'!Q21,'Model inputs'!Q18-1*1))="",FALSE,AND('Model inputs'!Q21<=DATE(2027,7,1),DATE(2027,7,1)<=EDATE('Model inputs'!Q21,'Model inputs'!Q18-1*1))),'Monthly revenue cost and runway'!J16,"")="",0,IF(IF(AND('Model inputs'!Q21<=DATE(2027,7,1),DATE(2027,7,1)<=EDATE('Model inputs'!Q21,'Model inputs'!Q18-1*1))="",FALSE,AND('Model inputs'!Q21<=DATE(2027,7,1),DATE(2027,7,1)<=EDATE('Model inputs'!Q21,'Model inputs'!Q18-1*1))),'Monthly revenue cost and runway'!J16,"")),IF(IF(IF(AND('Model inputs'!Q21<=DATE(2027,8,1),DATE(2027,8,1)<=EDATE('Model inputs'!Q21,'Model inputs'!Q18-1*1))="",FALSE,AND('Model inputs'!Q21<=DATE(2027,8,1),DATE(2027,8,1)<=EDATE('Model inputs'!Q21,'Model inputs'!Q18-1*1))),'Monthly revenue cost and runway'!K16,"")="",0,IF(IF(AND('Model inputs'!Q21<=DATE(2027,8,1),DATE(2027,8,1)<=EDATE('Model inputs'!Q21,'Model inputs'!Q18-1*1))="",FALSE,AND('Model inputs'!Q21<=DATE(2027,8,1),DATE(2027,8,1)<=EDATE('Model inputs'!Q21,'Model inputs'!Q18-1*1))),'Monthly revenue cost and runway'!K16,"")),IF(IF(IF(AND('Model inputs'!Q21<=DATE(2027,9,1),DATE(2027,9,1)<=EDATE('Model inputs'!Q21,'Model inputs'!Q18-1*1))="",FALSE,AND('Model inputs'!Q21<=DATE(2027,9,1),DATE(2027,9,1)<=EDATE('Model inputs'!Q21,'Model inputs'!Q18-1*1))),'Monthly revenue cost and runway'!L16,"")="",0,IF(IF(AND('Model inputs'!Q21<=DATE(2027,9,1),DATE(2027,9,1)<=EDATE('Model inputs'!Q21,'Model inputs'!Q18-1*1))="",FALSE,AND('Model inputs'!Q21<=DATE(2027,9,1),DATE(2027,9,1)<=EDATE('Model inputs'!Q21,'Model inputs'!Q18-1*1))),'Monthly revenue cost and runway'!L16,"")),IF(IF(IF(AND('Model inputs'!Q21<=DATE(2027,10,1),DATE(2027,10,1)<=EDATE('Model inputs'!Q21,'Model inputs'!Q18-1*1))="",FALSE,AND('Model inputs'!Q21<=DATE(2027,10,1),DATE(2027,10,1)<=EDATE('Model inputs'!Q21,'Model inputs'!Q18-1*1))),'Monthly revenue cost and runway'!M16,"")="",0,IF(IF(AND('Model inputs'!Q21<=DATE(2027,10,1),DATE(2027,10,1)<=EDATE('Model inputs'!Q21,'Model inputs'!Q18-1*1))="",FALSE,AND('Model inputs'!Q21<=DATE(2027,10,1),DATE(2027,10,1)<=EDATE('Model inputs'!Q21,'Model inputs'!Q18-1*1))),'Monthly revenue cost and runway'!M16,"")),IF(IF(IF(AND('Model inputs'!Q21<=DATE(2026,9,1),DATE(2026,9,1)<=EDATE('Model inputs'!Q21,'Model inputs'!Q18-1*1))="",FALSE,AND('Model inputs'!Q21<=DATE(2026,9,1),DATE(2026,9,1)<=EDATE('Model inputs'!Q21,'Model inputs'!Q18-1*1))),'Model inputs'!C42,"")="",0,IF(IF(AND('Model inputs'!Q21<=DATE(2026,9,1),DATE(2026,9,1)<=EDATE('Model inputs'!Q21,'Model inputs'!Q18-1*1))="",FALSE,AND('Model inputs'!Q21<=DATE(2026,9,1),DATE(2026,9,1)<=EDATE('Model inputs'!Q21,'Model inputs'!Q18-1*1))),'Model inputs'!C42,"")),IF(IF(IF(AND('Model inputs'!Q21<=DATE(2026,10,1),DATE(2026,10,1)<=EDATE('Model inputs'!Q21,'Model inputs'!Q18-1*1))="",FALSE,AND('Model inputs'!Q21<=DATE(2026,10,1),DATE(2026,10,1)<=EDATE('Model inputs'!Q21,'Model inputs'!Q18-1*1))),'Model inputs'!D42,"")="",0,IF(IF(AND('Model inputs'!Q21<=DATE(2026,10,1),DATE(2026,10,1)<=EDATE('Model inputs'!Q21,'Model inputs'!Q18-1*1))="",FALSE,AND('Model inputs'!Q21<=DATE(2026,10,1),DATE(2026,10,1)<=EDATE('Model inputs'!Q21,'Model inputs'!Q18-1*1))),'Model inputs'!D42,""))) -> 12420.2 | C6: =SUM(IF(IF(IF(AND('Model inputs'!Q23<=DATE(2026,10,1),DATE(2026,10,1)<=EDATE('Model inputs'!Q23,'Model inputs'!Q20-1*1))="",FALSE,AND('Model inputs'!Q23<=DATE(2026,10,1),DATE(2026,10,1)<=EDATE('Model inputs'!Q23,'Model inputs'!Q20-1*1))),'Model inputs'!D43,"")="",0,IF(IF(AND('Model inputs'!Q23<=DATE(2026,10,1),DATE(2026,10,1)<=EDATE('Model inputs'!Q23,'Model inputs'!Q20-1*1))="",FALSE,AND('Model inputs'!Q23<=DATE(2026,10,1),DATE(2026,10,1)<=EDATE('Model inputs'!Q23,'Model inputs'!Q20-1*1))),'Model inputs'!D43,"")),IF(IF(IF(AND('Model inputs'!Q23<=DATE(2026,11,1),DATE(2026,11,1)<=EDATE('Model inputs'!Q23,'Model inputs'!Q20-1*1))="",FALSE,AND('Model inputs'!Q23<=DATE(2026,11,1),DATE(2026,11,1)<=EDATE('Model inputs'!Q23,'Model inputs'!Q20-1*1))),'Model inputs'!E43,"")="",0,IF(IF(AND('Model inputs'!Q23<=DATE(2026,11,1),DATE(2026,11,1)<=EDATE('Model inputs'!Q23,'Model inputs'!Q20-1*1))="",FALSE,AND('Model inputs'!Q23<=DATE(2026,11,1),DATE(2026,11,1)<=EDATE('Model inputs'!Q23,'Model inputs'!Q20-1*1))),'Model inputs'!E43,"")),IF(IF(IF(AND('Model inputs'!Q23<=DATE(2026,12,1),DATE(2026,12,1)<=EDATE('Model inputs'!Q23,'Model inputs'!Q20-1*1))="",FALSE,AND('Model inputs'!Q23<=DATE(2026,12,1),DATE(2026,12,1)<=EDATE('Model inputs'!Q23,'Model inputs'!Q20-1*1))),'Model inputs'!F43,"")="",0,IF(IF(AND('Model inputs'!Q23<=DATE(2026,12,1),DATE(2026,12,1)<=EDATE('Model inputs'!Q23,'Model inputs'!Q20-1*1))="",FALSE,AND('Model inputs'!Q23<=DATE(2026,12,1),DATE(2026,12,1)<=EDATE('Model inputs'!Q23,'Model inputs'!Q20-1*1))),'Model inputs'!F43,"")),IF(IF(IF(AND('Model inputs'!Q23<=DATE(2027,1,1),DATE(2027,1,1)<=EDATE('Model inputs'!Q23,'Model inputs'!Q20-1*1))="",FALSE,AND('Model inputs'!Q23<=DATE(2027,1,1),DATE(2027,1,1)<=EDATE('Model inputs'!Q23,'Model inputs'!Q20-1*1))),'Model inputs'!G43,"")="",0,IF(IF(AND('Model inputs'!Q23<=DATE(2027,1,1),DATE(2027,1,1)<=EDATE('Model inputs'!Q23,'Model inputs'!Q20-1*1))="",FALSE,AND('Model inputs'!Q23<=DATE(2027,1,1),DATE(2027,1,1)<=EDATE('Model inputs'!Q23,'Model inputs'!Q20-1*1))),'Model inputs'!G43,"")),IF(IF(IF(AND('Model inputs'!Q23<=DATE(2027,2,1),DATE(2027,2,1)<=EDATE('Model inputs'!Q23,'Model inputs'!Q20-1*1))="",FALSE,AND('Model inputs'!Q23<=DATE(2027,2,1),DATE(2027,2,1)<=EDATE('Model inputs'!Q23,'Model inputs'!Q20-1*1))),'Model inputs'!H43,"")="",0,IF(IF(AND('Model inputs'!Q23<=DATE(2027,2,1),DATE(2027,2,1)<=EDATE('Model inputs'!Q23,'Model inputs'!Q20-1*1))="",FALSE,AND('Model inputs'!Q23<=DATE(2027,2,1),DATE(2027,2,1)<=EDATE('Model inputs'!Q23,'Model inputs'!Q20-1*1))),'Model inputs'!H43,"")),IF(IF(IF(AND('Model inputs'!Q23<=DATE(2027,3,1),DATE(2027,3,1)<=EDATE('Model inputs'!Q23,'Model inputs'!Q20-1*1))="",FALSE,AND('Model inputs'!Q23<=DATE(2027,3,1),DATE(2027,3,1)<=EDATE('Model inputs'!Q23,'Model inputs'!Q20-1*1))),'Model inputs'!I43,"")="",0,IF(IF(AND('Model inputs'!Q23<=DATE(2027,3,1),DATE(2027,3,1)<=EDATE('Model inputs'!Q23,'Model inputs'!Q20-1*1))="",FALSE,AND('Model inputs'!Q23<=DATE(2027,3,1),DATE(2027,3,1)<=EDATE('Model inputs'!Q23,'Model inputs'!Q20-1*1))),'Model inputs'!I43,"")),IF(IF(IF(AND('Model inputs'!Q23<=DATE(2027,4,1),DATE(2027,4,1)<=EDATE('Model inputs'!Q23,'Model inputs'!Q20-1*1))="",FALSE,AND('Model inputs'!Q23<=DATE(2027,4,1),DATE(2027,4,1)<=EDATE('Model inputs'!Q23,'Model inputs'!Q20-1*1))),'Model inputs'!J43,"")="",0,IF(IF(AND('Model inputs'!Q23<=DATE(2027,4,1),DATE(2027,4,1)<=EDATE('Model inputs'!Q23,'Model inputs'!Q20-1*1))="",FALSE,AND('Model inputs'!Q23<=DATE(2027,4,1),DATE(2027,4,1)<=EDATE('Model inputs'!Q23,'Model inputs'!Q20-1*1))),'Model inputs'!J43,"")),IF(IF(IF(AND('Model inputs'!Q23<=DATE(2027,5,1),DATE(2027,5,1)<=EDATE('Model inputs'!Q23,'Model inputs'!Q20-1*1))="",FALSE,AND('Model inputs'!Q23<=DATE(2027,5,1),DATE(2027,5,1)<=EDATE('Model inputs'!Q23,'Model inputs'!Q20-1*1))),'Model inputs'!K43,"")="",0,IF(IF(AND('Model inputs'!Q23<=DATE(2027,5,1),DATE(2027,5,1)<=EDATE('Model inputs'!Q23,'Model inputs'!Q20-1*1))="",FALSE,AND('Model inputs'!Q23<=DATE(2027,5,1),DATE(2027,5,1)<=EDATE('Model inputs'!Q23,'Model inputs'!Q20-1*1))),'Model inputs'!K43,"")),IF(IF(IF(AND('Model inputs'!Q23<=DATE(2027,6,1),DATE(2027,6,1)<=EDATE('Model inputs'!Q23,'Model inputs'!Q20-1*1))="",FALSE,AND('Model inputs'!Q23<=DATE(2027,6,1),DATE(2027,6,1)<=EDATE('Model inputs'!Q23,'Model inputs'!Q20-1*1))),'Model inputs'!L43,"")="",0,IF(IF(AND('Model inputs'!Q23<=DATE(2027,6,1),DATE(2027,6,1)<=EDATE('Model inputs'!Q23,'Model inputs'!Q20-1*1))="",FALSE,AND('Model inputs'!Q23<=DATE(2027,6,1),DATE(2027,6,1)<=EDATE('Model inputs'!Q23,'Model inputs'!Q20-1*1))),'Model inputs'!L43,"")),IF(IF(IF(AND('Model inputs'!Q23<=DATE(2027,7,1),DATE(2027,7,1)<=EDATE('Model inputs'!Q23,'Model inputs'!Q20-1*1))="",FALSE,AND('Model inputs'!Q23<=DATE(2027,7,1),DATE(2027,7,1)<=EDATE('Model inputs'!Q23,'Model inputs'!Q20-1*1))),'Model inputs'!M43,"")="",0,IF(IF(AND('Model inputs'!Q23<=DATE(2027,7,1),DATE(2027,7,1)<=EDATE('Model inputs'!Q23,'Model inputs'!Q20-1*1))="",FALSE,AND('Model inputs'!Q23<=DATE(2027,7,1),DATE(2027,7,1)<=EDATE('Model inputs'!Q23,'Model inputs'!Q20-1*1))),'Model inputs'!M43,"")),IF(IF(IF(AND('Model inputs'!Q23<=DATE(2027,8,1),DATE(2027,8,1)<=EDATE('Model inputs'!Q23,'Model inputs'!Q20-1*1))="",FALSE,AND('Model inputs'!Q23<=DATE(2027,8,1),DATE(2027,8,1)<=EDATE('Model inputs'!Q23,'Model inputs'!Q20-1*1))),'Model inputs'!N43,"")="",0,IF(IF(AND('Model inputs'!Q23<=DATE(2027,8,1),DATE(2027,8,1)<=EDATE('Model inputs'!Q23,'Model inputs'!Q20-1*1))="",FALSE,AND('Model inputs'!Q23<=DATE(2027,8,1),DATE(2027,8,1)<=EDATE('Model inputs'!Q23,'Model inputs'!Q20-1*1))),'Model inputs'!N43,"")),IF(IF(IF(AND('Model inputs'!Q23<=DATE(2027,9,1),DATE(2027,9,1)<=EDATE('Model inputs'!Q23,'Model inputs'!Q20-1*1))="",FALSE,AND('Model inputs'!Q23<=DATE(2027,9,1),DATE(2027,9,1)<=EDATE('Model inputs'!Q23,'Model inputs'!Q20-1*1))),'Model inputs'!O43,"")="",0,IF(IF(AND('Model inputs'!Q23<=DATE(2027,9,1),DATE(2027,9,1)<=EDATE('Model inputs'!Q23,'Model inputs'!Q20-1*1))="",FALSE,AND('Model inputs'!Q23<=DATE(2027,9,1),DATE(2027,9,1)<=EDATE('Model inputs'!Q23,'Model inputs'!Q20-1*1))),'Model inputs'!O43,"")),IF(IF(IF(AND('Model inputs'!Q23<=DATE(2027,10,1),DATE(2027,10,1)<=EDATE('Model inputs'!Q23,'Model inputs'!Q20-1*1))="",FALSE,AND('Model inputs'!Q23<=DATE(2027,10,1),DATE(2027,10,1)<=EDATE('Model inputs'!Q23,'Model inputs'!Q20-1*1))),'Model inputs'!P43,"")="",0,IF(IF(AND('Model inputs'!Q23<=DATE(2027,10,1),DATE(2027,10,1)<=EDATE('Model inputs'!Q23,'Model inputs'!Q20-1*1))="",FALSE,AND('Model inputs'!Q23<=DATE(2027,10,1),DATE(2027,10,1)<=EDATE('Model inputs'!Q23,'Model inputs'!Q20-1*1))),'Model inputs'!P43,"")),IF(IF(IF(AND('Model inputs'!Q23<=DATE(2026,9,1),DATE(2026,9,1)<=EDATE('Model inputs'!Q23,'Model inputs'!Q20-1*1))="",FALSE,AND('Model inputs'!Q23<=DATE(2026,9,1),DATE(2026,9,1)<=EDATE('Model inputs'!Q23,'Model inputs'!Q20-1*1))),'Model inputs'!C108,"")="",0,IF(IF(AND('Model inputs'!Q23<=DATE(2026,9,1),DATE(2026,9,1)<=EDATE('Model inputs'!Q23,'Model inputs'!Q20-1*1))="",FALSE,AND('Model inputs'!Q23<=DATE(2026,9,1),DATE(2026,9,1)<=EDATE('Model inputs'!Q23,'Model inputs'!Q20-1*1))),'Model inputs'!C108,""))) -> 96930.5
A7: 12-month net profit | B7: ='12-month forecast summary'!B5-'12-month forecast summary'!B6 -> 13487.8 | C7: ='12-month forecast summary'!C5-'12-month forecast summary'!C6 -> 539.5
A8: Forecast ending cash | B8: =IF(SUM(IF(IF('Model inputs'!B161="",0,1)="",0,IF('Model inputs'!B161="",0,1)),IF(IF('Model inputs'!B162="",0,1)="",0,IF('Model inputs'!B162="",0,1)),IF(IF('Model inputs'!B163="",0,1)="",0,IF('Model inputs'!B163="",0,1)),IF(IF('Model inputs'!B164="",0,1)="",0,IF('Model inputs'!B164="",0,1)),IF(IF('Model inputs'!B165="",0,1)="",0,IF('Model inputs'!B165="",0,1)),IF(IF('Model inputs'!B166="",0,1)="",0,IF('Model inputs'!B166="",0,1)),IF(IF('Model inputs'!B167="",0,1)="",0,IF('Model inputs'!B167="",0,1)),IF(IF('Model inputs'!B168="",0,1)="",0,IF('Model inputs'!B168="",0,1)),IF(IF('Model inputs'!B169="",0,1)="",0,IF('Model inputs'!B169="",0,1)),IF(IF('Model inputs'!B170="",0,1)="",0,IF('Model inputs'!B170="",0,1)),IF(IF('Model inputs'!B171="",0,1)="",0,IF('Model inputs'!B171="",0,1)),IF(IF('Model inputs'!B172="",0,1)="",0,IF('Model inputs'!B172="",0,1)),IF(IF('Model inputs'!B173="",0,1)="",0,IF('Model inputs'!B173="",0,1)),IF(IF('Model inputs'!B174="",0,1)="",0,IF('Model inputs'!B174="",0,1)))=0,"",SUM('Model inputs'!B161,'Model inputs'!B162,'Model inputs'!B163,'Model inputs'!B164,'Model inputs'!B165,'Model inputs'!B166,'Model inputs'!B167,'Model inputs'!B168,'Model inputs'!B169,'Model inputs'!B170,'Model inputs'!B171,'Model inputs'!B172,'Model inputs'!B173,'Model inputs'!B174)) -> 13487.8 | C8: =IF(SUM(IF(IF('Model inputs'!B175="",0,1)="",0,IF('Model inputs'!B175="",0,1)),IF(IF('Model inputs'!B176="",0,1)="",0,IF('Model inputs'!B176="",0,1)),IF(IF('Model inputs'!B177="",0,1)="",0,IF('Model inputs'!B177="",0,1)),IF(IF('Model inputs'!B178="",0,1)="",0,IF('Model inputs'!B178="",0,1)),IF(IF('Model inputs'!B179="",0,1)="",0,IF('Model inputs'!B179="",0,1)),IF(IF('Model inputs'!B180="",0,1)="",0,IF('Model inputs'!B180="",0,1)),IF(IF('Model inputs'!B181="",0,1)="",0,IF('Model inputs'!B181="",0,1)),IF(IF('Model inputs'!B182="",0,1)="",0,IF('Model inputs'!B182="",0,1)),IF(IF('Model inputs'!B183="",0,1)="",0,IF('Model inputs'!B183="",0,1)),IF(IF('Model inputs'!B184="",0,1)="",0,IF('Model inputs'!B184="",0,1)),IF(IF('Model inputs'!B185="",0,1)="",0,IF('Model inputs'!B185="",0,1)),IF(IF('Model inputs'!B186="",0,1)="",0,IF('Model inputs'!B186="",0,1)),IF(IF('Model inputs'!B187="",0,1)="",0,IF('Model inputs'!B187="",0,1)),IF(IF('Model inputs'!B188="",0,1)="",0,IF('Model inputs'!B188="",0,1)))=0,"",SUM('Model inputs'!B175,'Model inputs'!B176,'Model inputs'!B177,'Model inputs'!B178,'Model inputs'!B179,'Model inputs'!B180,'Model inputs'!B181,'Model inputs'!B182,'Model inputs'!B183,'Model inputs'!B184,'Model inputs'!B185,'Model inputs'!B186,'Model inputs'!B187,'Model inputs'!B188)) -> 539.5
A9: Minimum opening funding required | B9: =IF(SUM(IF(IF('Model inputs'!B189="",0,1)="",0,IF('Model inputs'!B189="",0,1)),IF(IF('Model inputs'!B190="",0,1)="",0,IF('Model inputs'!B190="",0,1)),IF(IF('Model inputs'!B191="",0,1)="",0,IF('Model inputs'!B191="",0,1)),IF(IF('Model inputs'!B192="",0,1)="",0,IF('Model inputs'!B192="",0,1)),IF(IF('Model inputs'!B193="",0,1)="",0,IF('Model inputs'!B193="",0,1)),IF(IF('Model inputs'!B194="",0,1)="",0,IF('Model inputs'!B194="",0,1)),IF(IF('Model inputs'!B195="",0,1)="",0,IF('Model inputs'!B195="",0,1)),IF(IF('Model inputs'!B196="",0,1)="",0,IF('Model inputs'!B196="",0,1)),IF(IF('Model inputs'!B197="",0,1)="",0,IF('Model inputs'!B197="",0,1)),IF(IF('Model inputs'!B198="",0,1)="",0,IF('Model inputs'!B198="",0,1)),IF(IF('Model inputs'!B199="",0,1)="",0,IF('Model inputs'!B199="",0,1)),IF(IF('Model inputs'!B200="",0,1)="",0,IF('Model inputs'!B200="",0,1)),IF(IF('Model inputs'!B201="",0,1)="",0,IF('Model inputs'!B201="",0,1)),IF(IF('Model inputs'!B202="",0,1)="",0,IF('Model inputs'!B202="",0,1)))=0,"",SUM('Model inputs'!B189,'Model inputs'!B190,'Model inputs'!B191,'Model inputs'!B192,'Model inputs'!B193,'Model inputs'!B194,'Model inputs'!B195,'Model inputs'!B196,'Model inputs'!B197,'Model inputs'!B198,'Model inputs'!B199,'Model inputs'!B200,'Model inputs'!B201,'Model inputs'!B202)) -> 45.7 | C9: =IF(SUM(IF(IF('Model inputs'!B203="",0,1)="",0,IF('Model inputs'!B203="",0,1)),IF(IF('Model inputs'!B204="",0,1)="",0,IF('Model inputs'!B204="",0,1)),IF(IF('Model inputs'!B205="",0,1)="",0,IF('Model inputs'!B205="",0,1)),IF(IF('Model inputs'!B206="",0,1)="",0,IF('Model inputs'!B206="",0,1)),IF(IF('Model inputs'!B207="",0,1)="",0,IF('Model inputs'!B207="",0,1)),IF(IF('Model inputs'!B208="",0,1)="",0,IF('Model inputs'!B208="",0,1)),IF(IF('Model inputs'!B209="",0,1)="",0,IF('Model inputs'!B209="",0,1)),IF(IF('Model inputs'!B210="",0,1)="",0,IF('Model inputs'!B210="",0,1)),IF(IF('Model inputs'!B211="",0,1)="",0,IF('Model inputs'!B211="",0,1)),IF(IF('Model inputs'!B212="",0,1)="",0,IF('Model inputs'!B212="",0,1)),IF(IF('Model inputs'!B213="",0,1)="",0,IF('Model inputs'!B213="",0,1)),IF(IF('Model inputs'!B214="",0,1)="",0,IF('Model inputs'!B214="",0,1)),IF(IF('Model inputs'!B215="",0,1)="",0,IF('Model inputs'!B215="",0,1)),IF(IF('Model inputs'!B216="",0,1)="",0,IF('Model inputs'!B216="",0,1)))=0,"",SUM('Model inputs'!B203,'Model inputs'!B204,'Model inputs'!B205,'Model inputs'!B206,'Model inputs'!B207,'Model inputs'!B208,'Model inputs'!B209,'Model inputs'!B210,'Model inputs'!B211,'Model inputs'!B212,'Model inputs'!B213,'Model inputs'!B214,'Model inputs'!B215,'Model inputs'!B216)) -> 4759.9773

Sheet Monthly revenue cost and runway
A1: Monthly revenue cost and runway
A2: Susanoo — 12-Month Forecast · Susanoo — Base
A4: Variable / dimension | B4: 2026-11 | C4: 2026-12 | D4: 2027-01 | E4: 2027-02 | F4: 2027-03 | G4: 2027-04 | H4: 2027-05 | I4: 2027-06 | J4: 2027-07 | K4: 2027-08 | L4: 2027-09 | M4: 2027-10
A5: Forecast subscription revenue | B5: =SUM('Customers revenue and run costs'!B11,'Customers revenue and run costs'!B12,'Customers revenue and run costs'!B13) -> 158 | C5: =SUM('Customers revenue and run costs'!C11,'Customers revenue and run costs'!C12,'Customers revenue and run costs'!C13) -> 430.90909 | D5: =SUM('Customers revenue and run costs'!D11,'Customers revenue and run costs'!D12,'Customers revenue and run costs'!D13) -> 703.81818 | E5: =SUM('Customers revenue and run costs'!E11,'Customers revenue and run costs'!E12,'Customers revenue and run costs'!E13) -> 976.72727 | F5: =SUM('Customers revenue and run costs'!F11,'Customers revenue and run costs'!F12,'Customers revenue and run costs'!F13) -> 1249.6364 | G5: =SUM('Customers revenue and run costs'!G11,'Customers revenue and run costs'!G12,'Customers revenue and run costs'!G13) -> 1522.5455 | H5: =SUM('Customers revenue and run costs'!H11,'Customers revenue and run costs'!H12,'Customers revenue and run costs'!H13) -> 1795.4545 | I5: =SUM('Customers revenue and run costs'!I11,'Customers revenue and run costs'!I12,'Customers revenue and run costs'!I13) -> 2068.3636 | ... M5: =SUM('Customers revenue and run costs'!M11,'Customers revenue and run costs'!M12,'Customers revenue and run costs'!M13) -> 4660
A6: Team revenue | B6: =IF('Customers revenue and run costs'!B13="","",'Customers revenue and run costs'!B13) -> 158 | C6: =IF('Customers revenue and run costs'!C13="","",'Customers revenue and run costs'!C13) -> 430.90909 | D6: =IF('Customers revenue and run costs'!D13="","",'Customers revenue and run costs'!D13) -> 703.81818 | E6: =IF('Customers revenue and run costs'!E13="","",'Customers revenue and run costs'!E13) -> 976.72727 | F6: =IF('Customers revenue and run costs'!F13="","",'Customers revenue and run costs'!F13) -> 1249.6364 | G6: =IF('Customers revenue and run costs'!G13="","",'Customers revenue and run costs'!G13) -> 1522.5455 | H6: =IF('Customers revenue and run costs'!H13="","",'Customers revenue and run costs'!H13) -> 1795.4545 | I6: =IF('Customers revenue and run costs'!I13="","",'Customers revenue and run costs'!I13) -> 2068.3636 | ... M6: =IF('Customers revenue and run costs'!M13="","",'Customers revenue and run costs'!M13) -> 3160
A7: Enterprise revenue | B7: =IF('Customers revenue and run costs'!B11="","",'Customers revenue and run costs'!B11) -> 0 | C7: =IF('Customers revenue and run costs'!C11="","",'Customers revenue and run costs'!C11) -> 0 | D7: =IF('Customers revenue and run costs'!D11="","",'Customers revenue and run costs'!D11) -> 0 | E7: =IF('Customers revenue and run costs'!E11="","",'Customers revenue and run costs'!E11) -> 0 | F7: =IF('Customers revenue and run costs'!F11="","",'Customers revenue and run costs'!F11) -> 0 | G7: =IF('Customers revenue and run costs'!G11="","",'Customers revenue and run costs'!G11) -> 0 | H7: =IF('Customers revenue and run costs'!H11="","",'Customers revenue and run costs'!H11) -> 0 | I7: =IF('Customers revenue and run costs'!I11="","",'Customers revenue and run costs'!I11) -> 0 | ... M7: =IF('Customers revenue and run costs'!M11="","",'Customers revenue and run costs'!M11) -> 1500
A8: Team run costs | B8: =IF('Customers revenue and run costs'!B17="","",'Customers revenue and run costs'!B17) -> 37.2 | C8: =IF('Customers revenue and run costs'!C17="","",'Customers revenue and run costs'!C17) -> 101.45455 | D8: =IF('Customers revenue and run costs'!D17="","",'Customers revenue and run costs'!D17) -> 165.70909 | E8: =IF('Customers revenue and run costs'!E17="","",'Customers revenue and run costs'!E17) -> 229.96364 | F8: =IF('Customers revenue and run costs'!F17="","",'Customers revenue and run costs'!F17) -> 294.21818 | G8: =IF('Customers revenue and run costs'!G17="","",'Customers revenue and run costs'!G17) -> 358.47273 | H8: =IF('Customers revenue and run costs'!H17="","",'Customers revenue and run costs'!H17) -> 422.72727 | I8: =IF('Customers revenue and run costs'!I17="","",'Customers revenue and run costs'!I17) -> 486.98182 | ... M8: =IF('Customers revenue and run costs'!M17="","",'Customers revenue and run costs'!M17) -> 744
A9: Enterprise run costs | B9: =IF('Customers revenue and run costs'!B15="","",'Customers revenue and run costs'!B15) -> 0 | C9: =IF('Customers revenue and run costs'!C15="","",'Customers revenue and run costs'!C15) -> 0 | D9: =IF('Customers revenue and run costs'!D15="","",'Customers revenue and run costs'!D15) -> 0 | E9: =IF('Customers revenue and run costs'!E15="","",'Customers revenue and run costs'!E15) -> 0 | F9: =IF('Customers revenue and run costs'!F15="","",'Customers revenue and run costs'!F15) -> 0 | G9: =IF('Customers revenue and run costs'!G15="","",'Customers revenue and run costs'!G15) -> 0 | H9: =IF('Customers revenue and run costs'!H15="","",'Customers revenue and run costs'!H15) -> 0 | I9: =IF('Customers revenue and run costs'!I15="","",'Customers revenue and run costs'!I15) -> 0 | ... M9: =IF('Customers revenue and run costs'!M15="","",'Customers revenue and run costs'!M15) -> 155
A10: Free run costs | B10: =IF('Customers revenue and run costs'!B16="","",'Customers revenue and run costs'!B16) -> 77.5 | C10: =IF('Customers revenue and run costs'!C16="","",'Customers revenue and run costs'!C16) -> 155 | D10: =IF('Customers revenue and run costs'!D16="","",'Customers revenue and run costs'!D16) -> 232.5 | E10: =IF('Customers revenue and run costs'!E16="","",'Customers revenue and run costs'!E16) -> 310 | F10: =IF('Customers revenue and run costs'!F16="","",'Customers revenue and run costs'!F16) -> 387.5 | G10: =IF('Customers revenue and run costs'!G16="","",'Customers revenue and run costs'!G16) -> 465 | H10: =IF('Customers revenue and run costs'!H16="","",'Customers revenue and run costs'!H16) -> 542.5 | I10: =IF('Customers revenue and run costs'!I16="","",'Customers revenue and run costs'!I16) -> 620 | ... M10: =IF('Customers revenue and run costs'!M16="","",'Customers revenue and run costs'!M16) -> 930
A11: Forecast run costs | B11: =SUM('Customers revenue and run costs'!B15,'Customers revenue and run costs'!B16,'Customers revenue and run costs'!B17) -> 114.7 | C11: =SUM('Customers revenue and run costs'!C15,'Customers revenue and run costs'!C16,'Customers revenue and run costs'!C17) -> 256.45455 | D11: =SUM('Customers revenue and run costs'!D15,'Customers revenue and run costs'!D16,'Customers revenue and run costs'!D17) -> 398.20909 | E11: =SUM('Customers revenue and run costs'!E15,'Customers revenue and run costs'!E16,'Customers revenue and run costs'!E17) -> 539.96364 | F11: =SUM('Customers revenue and run costs'!F15,'Customers revenue and run costs'!F16,'Customers revenue and run costs'!F17) -> 681.71818 | G11: =SUM('Customers revenue and run costs'!G15,'Customers revenue and run costs'!G16,'Customers revenue and run costs'!G17) -> 823.47273 | H11: =SUM('Customers revenue and run costs'!H15,'Customers revenue and run costs'!H16,'Customers revenue and run costs'!H17) -> 965.22727 | I11: =SUM('Customers revenue and run costs'!I15,'Customers revenue and run costs'!I16,'Customers revenue and run costs'!I17) -> 1106.9818 | ... M11: =SUM('Customers revenue and run costs'!M15,'Customers revenue and run costs'!M16,'Customers revenue and run costs'!M17) -> 1829
A12: Forecast gross profit | B12: ='Monthly revenue cost and runway'!B5-'Monthly revenue cost and runway'!B11 -> 43.3 | C12: ='Monthly revenue cost and runway'!C5-'Monthly revenue cost and runway'!C11 -> 174.45455 | D12: ='Monthly revenue cost and runway'!D5-'Monthly revenue cost and runway'!D11 -> 305.60909 | E12: ='Monthly revenue cost and runway'!E5-'Monthly revenue cost and runway'!E11 -> 436.76364 | F12: ='Monthly revenue cost and runway'!F5-'Monthly revenue cost and runway'!F11 -> 567.91818 | G12: ='Monthly revenue cost and runway'!G5-'Monthly revenue cost and runway'!G11 -> 699.07273 | H12: ='Monthly revenue cost and runway'!H5-'Monthly revenue cost and runway'!H11 -> 830.22727 | I12: ='Monthly revenue cost and runway'!I5-'Monthly revenue cost and runway'!I11 -> 961.38182 | ... M12: ='Monthly revenue cost and runway'!M5-'Monthly revenue cost and runway'!M11 -> 2831
A13: Forecast gross margin | B13: =IFERROR('Monthly revenue cost and runway'!B12/'Monthly revenue cost and runway'!B5,"") -> 0.27405063 | C13: =IFERROR('Monthly revenue cost and runway'!C12/'Monthly revenue cost and runway'!C5,"") -> 0.40485232 | D13: =IFERROR('Monthly revenue cost and runway'!D12/'Monthly revenue cost and runway'!D5,"") -> 0.43421596 | E13: =IFERROR('Monthly revenue cost and runway'!E12/'Monthly revenue cost and runway'!E5,"") -> 0.44717051 | F13: =IFERROR('Monthly revenue cost and runway'!F12/'Monthly revenue cost and runway'!F5,"") -> 0.45446675 | G13: =IFERROR('Monthly revenue cost and runway'!G12/'Monthly revenue cost and runway'!G5,"") -> 0.45914736 | H13: =IFERROR('Monthly revenue cost and runway'!H12/'Monthly revenue cost and runway'!H5,"") -> 0.46240506 | I13: =IFERROR('Monthly revenue cost and runway'!I12/'Monthly revenue cost and runway'!I5,"") -> 0.46480309 | ... M13: =IFERROR('Monthly revenue cost and runway'!M12/'Monthly revenue cost and runway'!M5,"") -> 0.60751073
A14: Forecast fixed costs | B14: =IF('Model inputs'!B15="","",'Model inputs'!B15) -> 89 | C14: =IF('Model inputs'!B15="","",'Model inputs'!B15) -> 89 | D14: =IF('Model inputs'!B15="","",'Model inputs'!B15) -> 89 | E14: =IF('Model inputs'!B15="","",'Model inputs'!B15) -> 89 | F14: =IF('Model inputs'!B15="","",'Model inputs'!B15) -> 89 | G14: =IF('Model inputs'!B15="","",'Model inputs'!B15) -> 89 | H14: =IF('Model inputs'!B15="","",'Model inputs'!B15) -> 89 | I14: =IF('Model inputs'!B15="","",'Model inputs'!B15) -> 89 | J14: =IF('Model inputs'!B15="","",'Model inputs'!B15) -> 89 | K14: =IF('Model inputs'!B15="","",'Model inputs'!B15) -> 89 | L14: =IF('Model inputs'!B15="","",'Model inputs'!B15) -> 89 | M14: =IF('Model inputs'!B15="","",'Model inputs'!B15) -> 89
A15: Forecast salaries | B15: =SUM('Monthly headcount and payroll'!B10,'Monthly headcount and payroll'!B11,'Monthly headcount and payroll'!B12) -> 0 | C15: =SUM('Monthly headcount and payroll'!C10,'Monthly headcount and payroll'!C11,'Monthly headcount and payroll'!C12) -> 0 | D15: =SUM('Monthly headcount and payroll'!D10,'Monthly headcount and payroll'!D11,'Monthly headcount and payroll'!D12) -> 0 | E15: =SUM('Monthly headcount and payroll'!E10,'Monthly headcount and payroll'!E11,'Monthly headcount and payroll'!E12) -> 0 | F15: =SUM('Monthly headcount and payroll'!F10,'Monthly headcount and payroll'!F11,'Monthly headcount and payroll'!F12) -> 0 | G15: =SUM('Monthly headcount and payroll'!G10,'Monthly headcount and payroll'!G11,'Monthly headcount and payroll'!G12) -> 0 | H15: =SUM('Monthly headcount and payroll'!H10,'Monthly headcount and payroll'!H11,'Monthly headcount and payroll'!H12) -> 0 | I15: =SUM('Monthly headcount and payroll'!I10,'Monthly headcount and payroll'!I11,'Monthly headcount and payroll'!I12) -> 0 | ... M15: =SUM('Monthly headcount and payroll'!M10,'Monthly headcount and payroll'!M11,'Monthly headcount and payroll'!M12) -> 0
A16: Total forecast costs | B16: ='Monthly revenue cost and runway'!B11+'Monthly revenue cost and runway'!B14+'Monthly revenue cost and runway'!B15 -> 203.7 | C16: ='Monthly revenue cost and runway'!C11+'Monthly revenue cost and runway'!C14+'Monthly revenue cost and runway'!C15 -> 345.45455 | D16: ='Monthly revenue cost and runway'!D11+'Monthly revenue cost and runway'!D14+'Monthly revenue cost and runway'!D15 -> 487.20909 | E16: ='Monthly revenue cost and runway'!E11+'Monthly revenue cost and runway'!E14+'Monthly revenue cost and runway'!E15 -> 628.96364 | F16: ='Monthly revenue cost and runway'!F11+'Monthly revenue cost and runway'!F14+'Monthly revenue cost and runway'!F15 -> 770.71818 | G16: ='Monthly revenue cost and runway'!G11+'Monthly revenue cost and runway'!G14+'Monthly revenue cost and runway'!G15 -> 912.47273 | H16: ='Monthly revenue cost and runway'!H11+'Monthly revenue cost and runway'!H14+'Monthly revenue cost and runway'!H15 -> 1054.2273 | I16: ='Monthly revenue cost and runway'!I11+'Monthly revenue cost and runway'!I14+'Monthly revenue cost and runway'!I15 -> 1195.9818 | ... M16: ='Monthly revenue cost and runway'!M11+'Monthly revenue cost and runway'!M14+'Monthly revenue cost and runway'!M15 -> 1918
A17: Net forecast profit | B17: ='Monthly revenue cost and runway'!B5-'Monthly revenue cost and runway'!B16 -> -45.7 | C17: ='Monthly revenue cost and runway'!C5-'Monthly revenue cost and runway'!C16 -> 85.454545 | D17: ='Monthly revenue cost and runway'!D5-'Monthly revenue cost and runway'!D16 -> 216.60909 | E17: ='Monthly revenue cost and runway'!E5-'Monthly revenue cost and runway'!E16 -> 347.76364 | F17: ='Monthly revenue cost and runway'!F5-'Monthly revenue cost and runway'!F16 -> 478.91818 | G17: ='Monthly revenue cost and runway'!G5-'Monthly revenue cost and runway'!G16 -> 610.07273 | H17: ='Monthly revenue cost and runway'!H5-'Monthly revenue cost and runway'!H16 -> 741.22727 | I17: ='Monthly revenue cost and runway'!I5-'Monthly revenue cost and runway'!I16 -> 872.38182 | ... M17: ='Monthly revenue cost and runway'!M5-'Monthly revenue cost and runway'!M16 -> 2742
A18: Net monthly burn | B18: =MAX(-'Monthly revenue cost and runway'!B17,0) -> 45.7 | C18: =MAX(-'Monthly revenue cost and runway'!C17,0) -> 0 | D18: =MAX(-'Monthly revenue cost and runway'!D17,0) -> 0 | E18: =MAX(-'Monthly revenue cost and runway'!E17,0) -> 0 | F18: =MAX(-'Monthly revenue cost and runway'!F17,0) -> 0 | G18: =MAX(-'Monthly revenue cost and runway'!G17,0) -> 0 | H18: =MAX(-'Monthly revenue cost and runway'!H17,0) -> 0 | I18: =MAX(-'Monthly revenue cost and runway'!I17,0) -> 0 | ... M18: =MAX(-'Monthly revenue cost and runway'!M17,0) -> 0
